Workbook
Name Candle: Mnu!$K$2:$K$61
Name CFL: Mnu!$J$2:$J$61
Name FTL: Mnu!$I$2:$I$61
Name Halogen: Mnu!$O$2:$O$61
Name HPS: Mnu!$P$2:$P$61
Name Incandescent: Mnu!$N$2:$N$61
Name LED_Bulb: Mnu!$S$2:$S$61
Name LED_Candle_Light: Mnu!$Z$2:$Z$61
Name LED_Downlight: Mnu!$U$2:$U$61
Name LED_Flood_Light: Mnu!$V$2:$V$61
Name LED_High_Bay: Mnu!$W$2:$W$61
Name LED_Panel_light: Mnu!$T$2:$T$61
Name LED_Spot_Light: Mnu!$R$2:$R$61
Name LED_Stick: Mnu!$Y$2:$Y$61
Name LED_Street_Light: Mnu!$X$2:$X$61
Name LED_Tube: Mnu!$Q$2:$Q$61
Name MH: Mnu!$L$2:$L$61
Name MV: Mnu!$M$2:$M$61

Sheet Project_Info

Sheet Instr.
C2: General instruction mentioned below to fill the sheet and Calculate savings.
C3: Please follow the below steps:
B5: Site Survey & Collection of the Light details
B6: Step 1
D7: Survey shall be done for all building in project scope.
C8: Light_Selection | D8: Start by filling out the Light_Selection Tab. This tab includes all registerd old models and also all registered new models. Just selected the existing old model and proposed replLightement.
D9: If models do not exist contLightt the Technical team
B11: Fill out the Sheet "OH"
B12: Step 2 | C12: OH | D12: Fill out the Operating Hours tab based on the approved operating hours by area and location recived from the entity. The
D13: Do not change any values on these cells.
D14: Identify the areas, location, building names, usage for all buildings under the scope.This will be reflected in the savings sheet.
D15: Sheet shall fill only with unique information like Building Name ,unique spLighte type and unique operation hours for the Light.
D16: If the building has multiple Light's with same spLighte type and same operation hours fill it once under the building Name.
D17: Identify the operating hours from 00:00:00 AM to 23:59:00 PM for all areas based on the letter from the entity or site collected information.
D18: Fillout no of days Light working per week & no of weeks Light working per year.
D19: If Light's are not operating during vLightation / off days, fill only working weeks and mention which weeks are not in operation.
B21: Fill out the Sheet "Light_Savings"
B22: Step 3
C23: Light_Savings | D23: Fill these cells based on site collected information as instructed below.
D24: Do not change any values on these cells.
D25: all values will be automatically generated.
D26: Select "Building Name" from dropdown list, followed by location description which contains spLighte type ,these location are only for the selcted building, other details will be autogenerated linked to OH table.
D27: Fillout above selected spLighte Floor no and existing Light area served in sq. meter.
D28: Fillout existing Light qty in that spLighte. Qty can be merged together if the spLighte type, Light opertaion timing and existing model specification are same.

Sheet Light_Selection
A1: S.N | B1: Baseline Unit Type | C1: Baseline Unit Description | D1: LED/Conv. | E1: Lamp/Fix | F1: Lamp Wattage | G1: Lumens | H1: Fixure Wattage | I1: Project Unit Type | J1: Lamp Load (W) | K1: Lumens | L1: CCT | M1: Model # | N1: Lamp/Fix. | O1: Fixure Wattage | P1: Savings% | Q1: Tarshid's Comments - R0 (x.xx.xxxx) | R1: ESCO Reply - R0 (x.xx.xxxx) | S1: Tarshid's Comments - R1 (x.xx.xxxx) | T1: ESCO Reply - R1 (xx.xx.xxxx) | U1: SN
A2: =U2&"- "&B2&"-"&F2&"W" -> 1- LED_Candle_Light-5W | B2: LED_Candle_Light | C2: LED_Candle_Light-E14-1X-5W | D2: {=IFERROR(VLOOKUP(C2,Old_Model_Registry!$B$2:$K$500,{3,10,8,9},0),"")} -> LED | E2: 1 | F2: 5 | G2: 350 | H2: =E2*F2 -> 5 | I2: LED Candle Light-Honeywell-E14-5W-4000K-500Lm | J2: {=IF(I2="No-Retrofit",F2,IFERROR(VLOOKUP(I2,Vstack!$A$2:$L$1000,{8},0),""))} -> 5 | K2: {=IF(I2="No-Retrofit",F2,IFERROR(VLOOKUP(I2,Vstack!$A$2:$L$1000,{9},0)*N2,""))} -> 500 | L2: {=IF(I2="No-Retrofit",F2,IFERROR(VLOOKUP(I2,Vstack!$A$2:$L$1000,{10,4},0),""))} -> 4000 | M2: Ess Candle 5W 4000K B35 220-240V E14 IP20 ND | N2: 1 | O2: =IFERROR(N2*J2,"") -> 5 | P2: =IFERROR(-(O2/H2-1),"") -> 0 | U2: 1
A3: =U3&"- "&B3&"-"&F3&"W" -> 2- CFL-35W | B3: CFL | C3: Conv-CFL-4Pin-1X-35W | D3: {=IFERROR(VLOOKUP(C3,Old_Model_Registry!$B$2:$K$500,{3,10,8,9},0),"")} -> Conv | E3: 1 | F3: 35 | G3: 1750 | H3: =E3*F3 -> 35 | I3: LED Bulb-Honeywell-E27-17.7W-4000K-1770Lm | J3: {=IF(I3="No-Retrofit",F3,IFERROR(VLOOKUP(I3,Vstack!$A$2:$L$1000,{8},0),""))} -> 17.7 | K3: {=IF(I3="No-Retrofit",F3,IFERROR(VLOOKUP(I3,Vstack!$A$2:$L$1000,{9},0)*N3,""))} -> 1770 | L3: {=IF(I3="No-Retrofit",F3,IFERROR(VLOOKUP(I3,Vstack!$A$2:$L$1000,{10,4},0),""))} -> 4000 | M3: Ess Bulb 17.7W 4000K A65 220-240V E27 IP20 ND | N3: 1 | O3: =IFERROR(N3*J3,"") -> 17.7 | P3: =IFERROR(-(O3/H3-1),"") -> 0.49428571 | U3: 2
A4: =U4&"- "&B4&"-"&F4&"W" -> 3- CFL-12W | B4: CFL | C4: Conv-CFL-E27-1X-12W | D4: {=IFERROR(VLOOKUP(C4,Old_Model_Registry!$B$2:$K$500,{3,10,8,9},0),"")} -> Conv | E4: 1 | F4: 12 | G4: 600 | H4: =E4*F4 -> 12 | I4: LED Stick-Honeywell-E27-7W-4000K-840Lm | J4: {=IF(I4="No-Retrofit",F4,IFERROR(VLOOKUP(I4,Vstack!$A$2:$L$1000,{8},0),""))} -> 7 | K4: {=IF(I4="No-Retrofit",F4,IFERROR(VLOOKUP(I4,Vstack!$A$2:$L$1000,{9},0)*N4,""))} -> 840 | L4: {=IF(I4="No-Retrofit",F4,IFERROR(VLOOKUP(I4,Vstack!$A$2:$L$1000,{10,4},0),""))} -> 4000 | M4: Ess Stick 7W 4000K T36 100-240V E27 IP20 ND | N4: 1 | O4: =IFERROR(N4*J4,"") -> 7 | P4: =IFERROR(-(O4/H4-1),"") -> 0.41666667 | U4: 3
A5: =U5&"- "&B5&"-"&F5&"W" -> 4- CFL-15W | B5: CFL | C5: Conv-CFL-E27-1X-15W | D5: {=IFERROR(VLOOKUP(C5,Old_Model_Registry!$B$2:$K$500,{3,10,8,9},0),"")} -> Conv | E5: 1 | F5: 15 | G5: 750 | H5: =E5*F5 -> 15 | I5: LED Stick-Honeywell-E27-7W-4000K-840Lm | J5: {=IF(I5="No-Retrofit",F5,IFERROR(VLOOKUP(I5,Vstack!$A$2:$L$1000,{8},0),""))} -> 7 | K5: {=IF(I5="No-Retrofit",F5,IFERROR(VLOOKUP(I5,Vstack!$A$2:$L$1000,{9},0)*N5,""))} -> 840 | L5: {=IF(I5="No-Retrofit",F5,IFERROR(VLOOKUP(I5,Vstack!$A$2:$L$1000,{10,4},0),""))} -> 4000 | M5: Ess Stick 7W 4000K T36 100-240V E27 IP20 ND | N5: 1 | O5: =IFERROR(N5*J5,"") -> 7 | P5: =IFERROR(-(O5/H5-1),"") -> 0.53333333 | U5: 4
A6: =U6&"- "&B6&"-"&F6&"W" -> 5- CFL-18W | B6: CFL | C6: Conv-CFL-E27-1X-18W | D6: {=IFERROR(VLOOKUP(C6,Old_Model_Registry!$B$2:$K$500,{3,10,8,9},0),"")} -> Conv | E6: 1 | F6: 18 | G6: 900 | H6: =E6*F6 -> 18 | I6: LED Stick-Honeywell-E27-9W-4000K-1080Lm | J6: {=IF(I6="No-Retrofit",F6,IFERROR(VLOOKUP(I6,Vstack!$A$2:$L$1000,{8},0),""))} -> 9 | K6: {=IF(I6="No-Retrofit",F6,IFERROR(VLOOKUP(I6,Vstack!$A$2:$L$1000,{9},0)*N6,""))} -> 1080 | L6: {=IF(I6="No-Retrofit",F6,IFERROR(VLOOKUP(I6,Vstack!$A$2:$L$1000,{10,4},0),""))} -> 4000 | M6: Ess Stick 9W 4000K T36 100-240V E27 IP20 ND | N6: 1 | O6: =IFERROR(N6*J6,"") -> 9 | P6: =IFERROR(-(O6/H6-1),"") -> 0.5 | U6: 5
A7: =U7&"- "&B7&"-"&F7&"W" -> 6- CFL-20W | B7: CFL | C7: Conv-CFL-E27-1X-20W | D7: {=IFERROR(VLOOKUP(C7,Old_Model_Registry!$B$2:$K$500,{3,10,8,9},0),"")} -> Conv | E7: 1 | F7: 20 | G7: 1000 | H7: =E7*F7 -> 20 | I7: LED Stick-Honeywell-E27-9W-4000K-1080Lm | J7: {=IF(I7="No-Retrofit",F7,IFERROR(VLOOKUP(I7,Vstack!$A$2:$L$1000,{8},0),""))} -> 9 | K7: {=IF(I7="No-Retrofit",F7,IFERROR(VLOOKUP(I7,Vstack!$A$2:$L$1000,{9},0)*N7,""))} -> 1080 | L7: {=IF(I7="No-Retrofit",F7,IFERROR(VLOOKUP(I7,Vstack!$A$2:$L$1000,{10,4},0),""))} -> 4000 | M7: Ess Stick 9W 4000K T36 100-240V E27 IP20 ND | N7: 1 | O7: =IFERROR(N7*J7,"") -> 9 | P7: =IFERROR(-(O7/H7-1),"") -> 0.55 | U7: 6
A8: =U8&"- "&B8&"-"&F8&"W" -> 7- CFL-23W | B8: CFL | C8: Conv-CFL-E27-1X-23W | D8: {=IFERROR(VLOOKUP(C8,Old_Model_Registry!$B$2:$K$500,{3,10,8,9},0),"")} -> Conv | E8: 1 | F8: 23 | G8: 1150 | H8: =E8*F8 -> 23 | I8: LED Stick-Honeywell-E27-10W-4000K-1200Lm | J8: {=IF(I8="No-Retrofit",F8,IFERROR(VLOOKUP(I8,Vstack!$A$2:$L$1000,{8},0),""))} -> 10 | K8: {=IF(I8="No-Retrofit",F8,IFERROR(VLOOKUP(I8,Vstack!$A$2:$L$1000,{9},0)*N8,""))} -> 1200 | L8: {=IF(I8="No-Retrofit",F8,IFERROR(VLOOKUP(I8,Vstack!$A$2:$L$1000,{10,4},0),""))} -> 4000 | M8: Ess Stick 10W 4000K T36 100-240V E27 IP20 ND | N8: 1 | O8: =IFERROR(N8*J8,"") -> 10 | P8: =IFERROR(-(O8/H8-1),"") -> 0.56521739 | U8: 7
A9: =U9&"- "&B9&"-"&F9&"W" -> 8- CFL-40W | B9: CFL | C9: Conv-CFL-E27-1X-40W | D9: {=IFERROR(VLOOKUP(C9,Old_Model_Registry!$B$2:$K$500,{3,10,8,9},0),"")} -> Conv | E9: 1 | F9: 40 | G9: 2000 | H9: =E9*F9 -> 40 | I9: LED HQL-Osram-E27-16W-4000K-2000Lm | J9: {=IF(I9="No-Retrofit",F9,IFERROR(VLOOKUP(I9,Vstack!$A$2:$L$1000,{8},0),""))} -> 16 | K9: {=IF(I9="No-Retrofit",F9,IFERROR(VLOOKUP(I9,Vstack!$A$2:$L$1000,{9},0)*N9,""))} -> 2000 | L9: {=IF(I9="No-Retrofit",F9,IFERROR(VLOOKUP(I9,Vstack!$A$2:$L$1000,{10,4},0),""))} -> 4000 | M9: HQLLED200016W/840230VPROE276X1G3KSAOSRAM | N9: 1 | O9: =IFERROR(N9*J9,"") -> 16 | P9: =IFERROR(-(O9/H9-1),"") -> 0.6 | U9: 8
A10: =U10&"- "&B10&"-"&F10&"W" -> 9- CFL-70W | B10: CFL | C10: Conv-CFL-E27-1X-70W | D10: {=IFERROR(VLOOKUP(C10,Old_Model_Registry!$B$2:$K$500,{3,10,8,9},0),"")} -> Conv | E10: 1 | F10: 70 | G10: 3500 | H10: =E10*F10 -> 70 | I10: LED High Watt Bulb-Honeywell-E27-25W-4000K-4375Lm | J10: {=IF(I10="No-Retrofit",F10,IFERROR(VLOOKUP(I10,Vstack!$A$2:$L$1000,{8},0),""))} -> 25 | K10: {=IF(I10="No-Retrofit",F10,IFERROR(VLOOKUP(I10,Vstack!$A$2:$L$1000,{9},0)*N10,""))} -> 4375 | L10: {=IF(I10="No-Retrofit",F10,IFERROR(VLOOKUP(I10,Vstack!$A$2:$L$1000,{10,4},0),""))} -> 4000 | M10: Ult HLL 25W 4000K 100-240V E27 IP65 ND | N10: 1 | O10: =IFERROR(N10*J10,"") -> 25 | P10: =IFERROR(-(O10/H10-1),"") -> 0.64285714 | U10: 9
A11: =U11&"- "&B11&"-"&F11&"W" -> 10- FTL-18W | B11: FTL | C11: Conv-FTL-T8-0.6M-1X-18W | D11: {=IFERROR(VLOOKUP(C11,Old_Model_Registry!$B$2:$K$500,{3,10,8,9},0),"")} -> Conv | E11: 1 | F11: 18 | G11: 900 | H11: =E11*F11 -> 18 | I11: LED Tube-Honeywell-T8-5.2W-4000K-1000Lm | J11: {=IF(I11="No-Retrofit",F11,IFERROR(VLOOKUP(I11,Vstack!$A$2:$L$1000,{8},0),""))} -> 5.2 | K11: {=IF(I11="No-Retrofit",F11,IFERROR(VLOOKUP(I11,Vstack!$A$2:$L$1000,{9},0)*N11,""))} -> 1000 | L11: {=IF(I11="No-Retrofit",F11,IFERROR(VLOOKUP(I11,Vstack!$A$2:$L$1000,{10,4},0),""))} -> 4000 | M11: Ult TLED T8 5.2W 4000K 60cm G13 IP20 ND | N11: 1 | O11: =IFERROR(N11*J11,"") -> 5.2 | P11: =IFERROR(-(O11/H11-1),"") -> 0.71111111 | U11: 10
A12: =U12&"- "&B12&"-"&F12&"W" -> 11- FTL-20W | B12: FTL | C12: Conv-FTL-T8-0.6M-1X-20W | D12: {=IFERROR(VLOOKUP(C12,Old_Model_Registry!$B$2:$K$500,{3,10,8,9},0),"")} -> Conv | E12: 1 | F12: 20 | G12: 1000 | H12: =E12*F12 -> 20 | I12: LED Tube-Honeywell-T8-5.2W-4000K-1000Lm | J12: {=IF(I12="No-Retrofit",F12,IFERROR(VLOOKUP(I12,Vstack!$A$2:$L$1000,{8},0),""))} -> 5.2 | K12: {=IF(I12="No-Retrofit",F12,IFERROR(VLOOKUP(I12,Vstack!$A$2:$L$1000,{9},0)*N12,""))} -> 1000 | L12: {=IF(I12="No-Retrofit",F12,IFERROR(VLOOKUP(I12,Vstack!$A$2:$L$1000,{10,4},0),""))} -> 4000 | M12: Ult TLED T8 5.2W 4000K 60cm G13 IP20 ND | N12: 1 | O12: =IFERROR(N12*J12,"") -> 5.2 | P12: =IFERROR(-(O12/H12-1),"") -> 0.74 | U12: 11
A13: =U13&"- "&B13&"-"&F13&"W" -> 12- FTL-14W | B13: FTL | C13: Conv-FTL-T8-1.2M-1X-14W | D13: {=IFERROR(VLOOKUP(C13,Old_Model_Registry!$B$2:$K$500,{3,10,8,9},0),"")} -> Conv | E13: 1 | F13: 14 | G13: 700 | H13: =E13*F13 -> 14 | I13: LED Tube-Honeywell-T8-8.7W-4000K-1800Lm | J13: {=IF(I13="No-Retrofit",F13,IFERROR(VLOOKUP(I13,Vstack!$A$2:$L$1000,{8},0),""))} -> 8.7 | K13: {=IF(I13="No-Retrofit",F13,IFERROR(VLOOKUP(I13,Vstack!$A$2:$L$1000,{9},0)*N13,""))} -> 1800 | L13: {=IF(I13="No-Retrofit",F13,IFERROR(VLOOKUP(I13,Vstack!$A$2:$L$1000,{10,4},0),""))} -> 4000 | M13: Ult TLED T8 8.7W 4000K 120cm G13 IP20 ND | N13: 1 | O13: =IFERROR(N13*J13,"") -> 8.7 | P13: =IFERROR(-(O13/H13-1),"") -> 0.37857143 | U13: 12
... A67: =U67&"- "&B67&"-"&F67&"W" -> 66- LED_Tube-10W | B67: LED_Tube | C67: LED_Tube--0.6M-1X-10W | D67: {=IFERROR(VLOOKUP(C67,Old_Model_Registry!$B$2:$K$500,{3,10,8,9},0),"")} -> LED | E67: 1 | F67: 10 | G67: 750 | H67: =E67*F67 -> 10 | I67: LED Tube-Honeywell-T8-5.2W-4000K-1000Lm | J67: {=IF(I67="No-Retrofit",F67,IFERROR(VLOOKUP(I67,Vstack!$A$2:$L$1000,{8},0),""))} -> 5.2 | K67: {=IF(I67="No-Retrofit",F67,IFERROR(VLOOKUP(I67,Vstack!$A$2:$L$1000,{9},0)*N67,""))} -> 1000 | L67: {=IF(I67="No-Retrofit",F67,IFERROR(VLOOKUP(I67,Vstack!$A$2:$L$1000,{10,4},0),""))} -> 4000 | M67: Ult TLED T8 5.2W 4000K 60cm G13 IP20 ND | N67: 1 | O67: =IFERROR(N67*J67,"") -> 5.2 | P67: =IFERROR(-(O67/H67-1),"") -> 0.48 | U67: 66
A68: =U68&"- "&B68&"-"&F68&"W" -> 67- -W | D68: {=IFERROR(VLOOKUP(C68,Old_Model_Registry!$B$2:$K$500,{3,10,8,9},0),"")} | H68: =E68*F68 -> 0 | J68: {=IF(I68="No-Retrofit",F68,IFERROR(VLOOKUP(I68,Vstack!$A$2:$L$1000,{8},0),""))} | K68: {=IF(I68="No-Retrofit",F68,IFERROR(VLOOKUP(I68,Vstack!$A$2:$L$1000,{9},0)*N68,""))} | L68: {=IF(I68="No-Retrofit",F68,IFERROR(VLOOKUP(I68,Vstack!$A$2:$L$1000,{10,4},0),""))} | O68: =IFERROR(N68*J68,"") | P68: =IFERROR(-(O68/H68-1),"") | U68: 67
A69: =U69&"- "&B69&"-"&F69&"W" -> 68- -W | D69: {=IFERROR(VLOOKUP(C69,Old_Model_Registry!$B$2:$K$500,{3,10,8,9},0),"")} | H69: =E69*F69 -> 0 | J69: {=IF(I69="No-Retrofit",F69,IFERROR(VLOOKUP(I69,Vstack!$A$2:$L$1000,{8},0),""))} | K69: {=IF(I69="No-Retrofit",F69,IFERROR(VLOOKUP(I69,Vstack!$A$2:$L$1000,{9},0)*N69,""))} | L69: {=IF(I69="No-Retrofit",F69,IFERROR(VLOOKUP(I69,Vstack!$A$2:$L$1000,{10,4},0),""))} | O69: =IFERROR(N69*J69,"") | P69: =IFERROR(-(O69/H69-1),"") | U69: 68
A70: =U70&"- "&B70&"-"&F70&"W" -> 69- -W | D70: {=IFERROR(VLOOKUP(C70,Old_Model_Registry!$B$2:$K$500,{3,10,8,9},0),"")} | H70: =E70*F70 -> 0 | J70: {=IF(I70="No-Retrofit",F70,IFERROR(VLOOKUP(I70,Vstack!$A$2:$L$1000,{8},0),""))} | K70: {=IF(I70="No-Retrofit",F70,IFERROR(VLOOKUP(I70,Vstack!$A$2:$L$1000,{9},0)*N70,""))} | L70: {=IF(I70="No-Retrofit",F70,IFERROR(VLOOKUP(I70,Vstack!$A$2:$L$1000,{10,4},0),""))} | O70: =IFERROR(N70*J70,"") | P70: =IFERROR(-(O70/H70-1),"") | U70: 69
A71: =U71&"- "&B71&"-"&F71&"W" -> 70- -W | D71: {=IFERROR(VLOOKUP(C71,Old_Model_Registry!$B$2:$K$500,{3,10,8,9},0),"")} | H71: =E71*F71 -> 0 | J71: {=IF(I71="No-Retrofit",F71,IFERROR(VLOOKUP(I71,Vstack!$A$2:$L$1000,{8},0),""))} | K71: {=IF(I71="No-Retrofit",F71,IFERROR(VLOOKUP(I71,Vstack!$A$2:$L$1000,{9},0)*N71,""))} | L71: {=IF(I71="No-Retrofit",F71,IFERROR(VLOOKUP(I71,Vstack!$A$2:$L$1000,{10,4},0),""))} | O71: =IFERROR(N71*J71,"") | P71: =IFERROR(-(O71/H71-1),"") | U71: 70
A72: =U72&"- "&B72&"-"&F72&"W" -> 71- -W | D72: {=IFERROR(VLOOKUP(C72,Old_Model_Registry!$B$2:$K$500,{3,10,8,9},0),"")} | H72: =E72*F72 -> 0 | J72: {=IF(I72="No-Retrofit",F72,IFERROR(VLOOKUP(I72,Vstack!$A$2:$L$1000,{8},0),""))} | K72: {=IF(I72="No-Retrofit",F72,IFERROR(VLOOKUP(I72,Vstack!$A$2:$L$1000,{9},0)*N72,""))} | L72: {=IF(I72="No-Retrofit",F72,IFERROR(VLOOKUP(I72,Vstack!$A$2:$L$1000,{10,4},0),""))} | O72: =IFERROR(N72*J72,"") | P72: =IFERROR(-(O72/H72-1),"") | U72: 71
A73: =U73&"- "&B73&"-"&F73&"W" -> 72- -W | D73: {=IFERROR(VLOOKUP(C73,Old_Model_Registry!$B$2:$K$500,{3,10,8,9},0),"")} | H73: =E73*F73 -> 0 | J73: {=IF(I73="No-Retrofit",F73,IFERROR(VLOOKUP(I73,Vstack!$A$2:$L$1000,{8},0),""))} | K73: {=IF(I73="No-Retrofit",F73,IFERROR(VLOOKUP(I73,Vstack!$A$2:$L$1000,{9},0)*N73,""))} | L73: {=IF(I73="No-Retrofit",F73,IFERROR(VLOOKUP(I73,Vstack!$A$2:$L$1000,{10,4},0),""))} | O73: =IFERROR(N73*J73,"") | P73: =IFERROR(-(O73/H73-1),"") | U73: 72
A74: =U74&"- "&B74&"-"&F74&"W" -> 73- -W | D74: {=IFERROR(VLOOKUP(C74,Old_Model_Registry!$B$2:$K$500,{3,10,8,9},0),"")} | H74: =E74*F74 -> 0 | J74: {=IF(I74="No-Retrofit",F74,IFERROR(VLOOKUP(I74,Vstack!$A$2:$L$1000,{8},0),""))} | K74: {=IF(I74="No-Retrofit",F74,IFERROR(VLOOKUP(I74,Vstack!$A$2:$L$1000,{9},0)*N74,""))} | L74: {=IF(I74="No-Retrofit",F74,IFERROR(VLOOKUP(I74,Vstack!$A$2:$L$1000,{10,4},0),""))} | O74: =IFERROR(N74*J74,"") | P74: =IFERROR(-(O74/H74-1),"") | U74: 73
A75: =U75&"- "&B75&"-"&F75&"W" -> 74- -W | D75: {=IFERROR(VLOOKUP(C75,Old_Model_Registry!$B$2:$K$500,{3,10,8,9},0),"")} | H75: =E75*F75 -> 0 | J75: {=IF(I75="No-Retrofit",F75,IFERROR(VLOOKUP(I75,Vstack!$A$2:$L$1000,{8},0),""))} | K75: {=IF(I75="No-Retrofit",F75,IFERROR(VLOOKUP(I75,Vstack!$A$2:$L$1000,{9},0)*N75,""))} | L75: {=IF(I75="No-Retrofit",F75,IFERROR(VLOOKUP(I75,Vstack!$A$2:$L$1000,{10,4},0),""))} | O75: =IFERROR(N75*J75,"") | P75: =IFERROR(-(O75/H75-1),"") | U75: 74
A76: =U76&"- "&B76&"-"&F76&"W" -> 75- -W | D76: {=IFERROR(VLOOKUP(C76,Old_Model_Registry!$B$2:$K$500,{3,10,8,9},0),"")} | H76: =E76*F76 -> 0 | J76: {=IF(I76="No-Retrofit",F76,IFERROR(VLOOKUP(I76,Vstack!$A$2:$L$1000,{8},0),""))} | K76: {=IF(I76="No-Retrofit",F76,IFERROR(VLOOKUP(I76,Vstack!$A$2:$L$1000,{9},0)*N76,""))} | L76: {=IF(I76="No-Retrofit",F76,IFERROR(VLOOKUP(I76,Vstack!$A$2:$L$1000,{10,4},0),""))} | O76: =IFERROR(N76*J76,"") | P76: =IFERROR(-(O76/H76-1),"") | U76: 75
A77: =U77&"- "&B77&"-"&F77&"W" -> 76- -W | D77: {=IFERROR(VLOOKUP(C77,Old_Model_Registry!$B$2:$K$500,{3,10,8,9},0),"")} | H77: =E77*F77 -> 0 | J77: {=IF(I77="No-Retrofit",F77,IFERROR(VLOOKUP(I77,Vstack!$A$2:$L$1000,{8},0),""))} | K77: {=IF(I77="No-Retrofit",F77,IFERROR(VLOOKUP(I77,Vstack!$A$2:$L$1000,{9},0)*N77,""))} | L77: {=IF(I77="No-Retrofit",F77,IFERROR(VLOOKUP(I77,Vstack!$A$2:$L$1000,{10,4},0),""))} | O77: =IFERROR(N77*J77,"") | P77: =IFERROR(-(O77/H77-1),"") | U77: 76
A78: =U78&"- "&B78&"-"&F78&"W" -> 77- -W | D78: {=IFERROR(VLOOKUP(C78,Old_Model_Registry!$B$2:$K$500,{3,10,8,9},0),"")} | H78: =E78*F78 -> 0 | J78: {=IF(I78="No-Retrofit",F78,IFERROR(VLOOKUP(I78,Vstack!$A$2:$L$1000,{8},0),""))} | K78: {=IF(I78="No-Retrofit",F78,IFERROR(VLOOKUP(I78,Vstack!$A$2:$L$1000,{9},0)*N78,""))} | L78: {=IF(I78="No-Retrofit",F78,IFERROR(VLOOKUP(I78,Vstack!$A$2:$L$1000,{10,4},0),""))} | O78: =IFERROR(N78*J78,"") | P78: =IFERROR(-(O78/H78-1),"") | U78: 77
A79: =U79&"- "&B79&"-"&F79&"W" -> 78- -W | D79: {=IFERROR(VLOOKUP(C79,Old_Model_Registry!$B$2:$K$500,{3,10,8,9},0),"")} | H79: =E79*F79 -> 0 | J79: {=IF(I79="No-Retrofit",F79,IFERROR(VLOOKUP(I79,Vstack!$A$2:$L$1000,{8},0),""))} | K79: {=IF(I79="No-Retrofit",F79,IFERROR(VLOOKUP(I79,Vstack!$A$2:$L$1000,{9},0)*N79,""))} | L79: {=IF(I79="No-Retrofit",F79,IFERROR(VLOOKUP(I79,Vstack!$A$2:$L$1000,{10,4},0),""))} | O79: =IFERROR(N79*J79,"") | P79: =IFERROR(-(O79/H79-1),"") | U79: 78
... A501: =U501&"- "&B501&"-"&F501&"W" -> 500- -W | D501: {=IFERROR(VLOOKUP(C501,Old_Model_Registry!$B$2:$K$500,{3,10,8,9},0),"")} | H501: =E501*F501 -> 0 | J501: {=IF(I501="No-Retrofit",F501,IFERROR(VLOOKUP(I501,Vstack!$A$2:$L$1000,{8},0),""))} | K501: {=IF(I501="No-Retrofit",F501,IFERROR(VLOOKUP(I501,Vstack!$A$2:$L$1000,{9},0)*N501,""))} | L501: {=IF(I501="No-Retrofit",F501,IFERROR(VLOOKUP(I501,Vstack!$A$2:$L$1000,{10,4},0),""))} | O501: =IFERROR(N501*J501,"") | P501: =IFERROR(-(O501/H501-1),"") | U501: 500

Sheet OH
A1: For Coding Use do not erase | B1: # | C1: City | D1: Entity Name | E1: Facility Location | F1: Zone/Building Number/Coordinates | G1: Others (Example. Coordinates) | H1: Building Name | I1: Combined Value | J1: Space type | K1: Operating hours (Start time) | L1: Operating hours ( End time) | M1: أيام العمل الفعلية أسبوعياً /Working days per week | N1: عدد الاسابيع في السنة /Weeks per year | O1: Operating hours refrence | P1: التشغيل / سنة /Operating hours per year | Q1: EFLH

Sheet Light_Savings
J1: ESM | K1: BOQ | L1: Baseline Lighting Consumption (kWh) | M1: Project Lighting Consumption(kWh) | N1: Energy Savings (kWh) | O1: % Savings
J2: Lighting Replacement Conventional to LED | K2: =SUMIFS($V$12:$V$5011,$R$12:$R$5011,"<>No-Retrofit",$K$12:$K$5011,"Conv") | L2: =SUMIFS($Q$12:$Q$5011,$R$12:$R$5011,"<>No-Retrofit",$K$12:$K$5011,"Conv") | M2: =IFERROR((L5-N5),"") | N2: =SUMIF($K$12:$K$5011,"Conv",$Z$12:$Z$5011) | O2: =IFERROR(N2/L2," ")
J3: Lighting Replacement LED to LED | K3: =SUMIFS($V$12:$V$5011,$K$12:$K$5011,"LED",$R$12:$R$5011,"<>No-Retrofit") | L3: =SUMIFS($Q$12:$Q$5011,$K$12:$K$5011,"LED",$R$12:$R$5011,"<>No-Retrofit") | N3: =SUMIF($K$12:$K$5011,"LED",$Z$12:$Z$5011) | O3: =IFERROR(N3/L3," ")
J4: Lighting Control | K4: =+AC10 | L4: =AD10 | N4: =+AE10 | O4: =IFERROR(N4/L4," ")
J5: Total | K5: =SUM(K2:K3) | L5: =SUM(L2:L3) | N5: =+IFERROR(SUM(N2:N4),"") | O5: =N5/L5
A10: Summary | I10: =SUMIF($R$12:$R$5011,"<>No-Retrofit",$I$12:$I$5011) | O10: =SUMIF($R$12:$R$5011,"<>No-Retrofit",$O$12:$O$5011) | P10: =SUMIF($R$12:$R$5011,"<>No-Retrofit",$P$12:$P$5011) | Q10: =SUMIF($R$12:$R$5011,"<>No-Retrofit",$Q$12:$Q$5011) | V10: =SUMIF($R$12:$R$5011,"<>No-Retrofit",$V$12:$V$5011) | X10: =SUM(Light_Savings!$X$12:$X$5011) | Y10: =SUMIF($R$12:$R$5011,"<>No-Retrofit",$Y$12:$Y$5011) | Z10: =SUM(Light_Savings!$Z$12:$Z$5011) | AC10: =+SUM(Light_Savings!$AC$12:$AC$5011) | AD10: =SUM(Light_Savings!$AD$12:$AD$5011) | AE10: =+IFERROR(SUM(Light_Savings!$AE$12:$AE$5011),"")
A11: S.N | B11: Building Name | C11: Location | D11: Zone/Building No. | E11: Space Category | F11: Operating hours refrence | G11: Operating Hour | H11: Lighting Selection S.N | I11: Fix Qunatity | J11: Baseline unit Description | K11: LED/CONV | L11: Lamp/Fix | M11: Lamp Load (W) | N11: Fix Wattage | O11: Lamp Qty | P11: Total Load [kW] | Q11: Baseline Energy Consumption (kWh) | R11: Project Unit Description | S11: Lamp/Fix. | T11: Model # | U11: Lamp Load [W] | V11: Lamp Qty | W11: Fix Load [W] | X11: Total Load[kW] | Y11: Energy Consumption of Project Lighting Units (kWh) | Z11: Energy Savings (kWh) | AB11: Is there a light control? | AC11: Sensors Qty | AD11: Control- Baselined kWh | AE11: Control - Savings kWh | AF11: Installed Yes / No

Sheet Pivot

Sheet Pivot_2
H1: Summary Table Projects units

Sheet Pivot_Cntrl

Sheet Pivot_Baseline

Sheet Old_Model_Registry
A1: Sr. No. | B1: Surveyed Unit Description | C1: Lamp Type | D1: Conv./LED | E1: Location Type (Interior/Exterior) | F1: Shape/Size/Base | G1: Length/Width/Diameter | H1: Lamp/Fixture | I1: Wattage (W) | J1: Lumens (lm) | K1: Lamp/Fix | L1: Check
A2: 1 | B2: Conv-FTL-T8-1.5M-1X-56W | C2: FTL | D2: Conv | E2: Interior | F2: T8 | G2: 1.5M- | H2: 1X | I2: 56 | J2: 2800 | K2: 1
A3: 2 | B3: =IF(C3="","",IF(D3="Conv",IFERROR(D3&"-"&C3&"-"&F3&"-"&G3&""&H3&"-"&I3&"W",""),IFERROR(C3&"-"&F3&"-"&G3&""&H3&"-"&I3&"W",""))) -> Conv-FTL-T8-1.5M-2X-56W | C3: FTL | D3: Conv | E3: Interior | F3: T8 | G3: 1.5M- | H3: 2X | I3: 56 | J3: 5600 | K3: 2
A4: 3 | B4: =IF(C4="","",IF(D4="Conv",IFERROR(D4&"-"&C4&"-"&F4&"-"&G4&""&H4&"-"&I4&"W",""),IFERROR(C4&"-"&F4&"-"&G4&""&H4&"-"&I4&"W",""))) -> Conv-FTL-T8-1.5M-3X-56W | C4: FTL | D4: Conv | E4: Interior | F4: T8 | G4: 1.5M- | H4: 3X | I4: 56 | J4: 8400 | K4: 3
A5: 4 | B5: =IF(C5="","",IF(D5="Conv",IFERROR(D5&"-"&C5&"-"&F5&"-"&G5&""&H5&"-"&I5&"W",""),IFERROR(C5&"-"&F5&"-"&G5&""&H5&"-"&I5&"W",""))) -> Conv-FTL-T8-1.5M-4X-56W | C5: FTL | D5: Conv | E5: Interior | F5: T8 | G5: 1.5M- | H5: 4X | I5: 56 | J5: 11200 | K5: 4
A6: 5 | B6: =IF(C6="","",IF(D6="Conv",IFERROR(D6&"-"&C6&"-"&F6&"-"&G6&""&H6&"-"&I6&"W",""),IFERROR(C6&"-"&F6&"-"&G6&""&H6&"-"&I6&"W",""))) -> Conv-FTL-T12-1.2M-1X-40W | C6: FTL | D6: Conv | E6: Interior | F6: T12 | G6: 1.2M- | H6: 1X | I6: 40 | J6: =IFERROR(K6*I6*VLOOKUP(C6,Mnu!$E$20:$F$37,2,FALSE)," ") -> 2000 | K6: 1
A7: 6 | B7: =IF(C7="","",IF(D7="Conv",IFERROR(D7&"-"&C7&"-"&F7&"-"&G7&""&H7&"-"&I7&"W",""),IFERROR(C7&"-"&F7&"-"&G7&""&H7&"-"&I7&"W",""))) -> Conv-FTL-T12-1.2M-2X-40W | C7: FTL | D7: Conv | E7: Interior | F7: T12 | G7: 1.2M- | H7: 2X | I7: 40 | J7: =IFERROR(K7*I7*VLOOKUP(C7,Mnu!$E$20:$F$37,2,FALSE)," ") -> 4000 | K7: 2
A8: 7 | B8: =IF(C8="","",IF(D8="Conv",IFERROR(D8&"-"&C8&"-"&F8&"-"&G8&""&H8&"-"&I8&"W",""),IFERROR(C8&"-"&F8&"-"&G8&""&H8&"-"&I8&"W",""))) -> Conv-FTL-T12-1.2M-3X-40W | C8: FTL | D8: Conv | E8: Interior | F8: T12 | G8: 1.2M- | H8: 3X | I8: 40 | J8: =IFERROR(K8*I8*VLOOKUP(C8,Mnu!$E$20:$F$37,2,FALSE)," ") -> 6000 | K8: 3
A9: 8 | B9: =IF(C9="","",IF(D9="Conv",IFERROR(D9&"-"&C9&"-"&F9&"-"&G9&""&H9&"-"&I9&"W",""),IFERROR(C9&"-"&F9&"-"&G9&""&H9&"-"&I9&"W",""))) -> Conv-FTL-T12-1.2M-4X-40W | C9: FTL | D9: Conv | E9: Interior | F9: T12 | G9: 1.2M- | H9: 4X | I9: 40 | J9: =IFERROR(K9*I9*VLOOKUP(C9,Mnu!$E$20:$F$37,2,FALSE)," ") -> 8000 | K9: 4
A10: 9 | B10: =IF(C10="","",IF(D10="Conv",IFERROR(D10&"-"&C10&"-"&F10&"-"&G10&""&H10&"-"&I10&"W",""),IFERROR(C10&"-"&F10&"-"&G10&""&H10&"-"&I10&"W",""))) -> Conv-FTL-T8-1.2M-1X-36W | C10: FTL | D10: Conv | E10: Interior | F10: T8 | G10: 1.2M- | H10: 1X | I10: 36 | J10: =IFERROR(K10*I10*VLOOKUP(C10,Mnu!$E$20:$F$37,2,FALSE)," ") -> 1800 | K10: 1
A11: 10 | B11: =IF(C11="","",IF(D11="Conv",IFERROR(D11&"-"&C11&"-"&F11&"-"&G11&""&H11&"-"&I11&"W",""),IFERROR(C11&"-"&F11&"-"&G11&""&H11&"-"&I11&"W",""))) -> Conv-FTL-T8-1.2M-2X-36W | C11: FTL | D11: Conv | E11: Interior | F11: T8 | G11: 1.2M- | H11: 2X | I11: 36 | J11: =IFERROR(K11*I11*VLOOKUP(C11,Mnu!$E$20:$F$37,2,FALSE)," ") -> 3600 | K11: 2
A12: 11 | B12: =IF(C12="","",IF(D12="Conv",IFERROR(D12&"-"&C12&"-"&F12&"-"&G12&""&H12&"-"&I12&"W",""),IFERROR(C12&"-"&F12&"-"&G12&""&H12&"-"&I12&"W",""))) -> Conv-FTL-T8-1.2M-3X-36W | C12: FTL | D12: Conv | E12: Interior | F12: T8 | G12: 1.2M- | H12: 3X | I12: 36 | J12: =IFERROR(K12*I12*VLOOKUP(C12,Mnu!$E$20:$F$37,2,FALSE)," ") -> 5400 | K12: 3
A13: 12 | B13: =IF(C13="","",IF(D13="Conv",IFERROR(D13&"-"&C13&"-"&F13&"-"&G13&""&H13&"-"&I13&"W",""),IFERROR(C13&"-"&F13&"-"&G13&""&H13&"-"&I13&"W",""))) -> Conv-FTL-T8-1.2M-4X-36W | C13: FTL | D13: Conv | E13: Interior | F13: T8 | G13: 1.2M- | H13: 4X | I13: 36 | J13: =IFERROR(K13*I13*VLOOKUP(C13,Mnu!$E$20:$F$37,2,FALSE)," ") -> 7200 | K13: 4
A14: 13 | B14: =IF(C14="","",IF(D14="Conv",IFERROR(D14&"-"&C14&"-"&F14&"-"&G14&""&H14&"-"&I14&"W",""),IFERROR(C14&"-"&F14&"-"&G14&""&H14&"-"&I14&"W",""))) -> Conv-FTL-T12-0.6M-1X-20W | C14: FTL | D14: Conv | E14: Interior | F14: T12 | G14: 0.6M- | H14: 1X | I14: 20 | J14: =IFERROR(K14*I14*VLOOKUP(C14,Mnu!$E$20:$F$37,2,FALSE)," ") -> 1000 | K14: 1
A15: 14 | B15: =IF(C15="","",IF(D15="Conv",IFERROR(D15&"-"&C15&"-"&F15&"-"&G15&""&H15&"-"&I15&"W",""),IFERROR(C15&"-"&F15&"-"&G15&""&H15&"-"&I15&"W",""))) -> Conv-FTL-T12-0.6M-2X-20W | C15: FTL | D15: Conv | E15: Interior | F15: T12 | G15: 0.6M- | H15: 2X | I15: 20 | J15: =IFERROR(K15*I15*VLOOKUP(C15,Mnu!$E$20:$F$37,2,FALSE)," ") -> 2000 | K15: 2
A16: 15 | B16: =IF(C16="","",IF(D16="Conv",IFERROR(D16&"-"&C16&"-"&F16&"-"&G16&""&H16&"-"&I16&"W",""),IFERROR(C16&"-"&F16&"-"&G16&""&H16&"-"&I16&"W",""))) -> Conv-FTL-T12-0.6M-3X-20W | C16: FTL | D16: Conv | E16: Interior | F16: T12 | G16: 0.6M- | H16: 3X | I16: 20 | J16: =IFERROR(K16*I16*VLOOKUP(C16,Mnu!$E$20:$F$37,2,FALSE)," ") -> 3000 | K16: 3
A17: 16 | B17: =IF(C17="","",IF(D17="Conv",IFERROR(D17&"-"&C17&"-"&F17&"-"&G17&""&H17&"-"&I17&"W",""),IFERROR(C17&"-"&F17&"-"&G17&""&H17&"-"&I17&"W",""))) -> Conv-FTL-T12-0.6M-4X-20W | C17: FTL | D17: Conv | E17: Interior | F17: T12 | G17: 0.6M- | H17: 4X | I17: 20 | J17: =IFERROR(K17*I17*VLOOKUP(C17,Mnu!$E$20:$F$37,2,FALSE)," ") -> 4000 | K17: 4
... A33: 32 | B33: =IF(C33="","",IF(D33="Conv",IFERROR(D33&"-"&C33&"-"&F33&"-"&G33&""&H33&"-"&I33&"W",""),IFERROR(C33&"-"&F33&"-"&G33&""&H33&"-"&I33&"W",""))) -> Conv-FTL-T5-0.6M-4X-14W | C33: FTL | D33: Conv | E33: Interior | F33: T5 | G33: 0.6M- | H33: 4X | I33: 14 | J33: =IFERROR(K33*I33*VLOOKUP(C33,Mnu!$E$20:$F$37,2,FALSE)," ") -> 2800 | K33: 4
A34: 33 | B34: =IF(C34="","",IF(D34="Conv",IFERROR(D34&"-"&C34&"-"&F34&"-"&G34&""&H34&"-"&I34&"W",""),IFERROR(C34&"-"&F34&"-"&G34&""&H34&"-"&I34&"W",""))) -> Conv-CFL-E27-1X-9W | C34: CFL | D34: Conv | E34: Interior | F34: E27 | H34: 1X | I34: 9 | J34: =IFERROR(K34*I34*VLOOKUP(C34,Mnu!$E$20:$F$37,2,FALSE)," ") -> 450 | K34: 1
A35: 34 | B35: =IF(C35="","",IF(D35="Conv",IFERROR(D35&"-"&C35&"-"&F35&"-"&G35&""&H35&"-"&I35&"W",""),IFERROR(C35&"-"&F35&"-"&G35&""&H35&"-"&I35&"W",""))) -> Conv-CFL-E27-1X-10W | C35: CFL | D35: Conv | E35: Interior | F35: E27 | H35: 1X | I35: 10 | J35: =IFERROR(K35*I35*VLOOKUP(C35,Mnu!$E$20:$F$37,2,FALSE)," ") -> 500 | K35: 1
A36: 35 | B36: =IF(C36="","",IF(D36="Conv",IFERROR(D36&"-"&C36&"-"&F36&"-"&G36&""&H36&"-"&I36&"W",""),IFERROR(C36&"-"&F36&"-"&G36&""&H36&"-"&I36&"W",""))) -> Conv-CFL-E27-1X-12W | C36: CFL | D36: Conv | E36: Interior | F36: E27 | H36: 1X | I36: 12 | J36: =IFERROR(K36*I36*VLOOKUP(C36,Mnu!$E$20:$F$37,2,FALSE)," ") -> 600 | K36: 1
A37: 36 | B37: =IF(C37="","",IF(D37="Conv",IFERROR(D37&"-"&C37&"-"&F37&"-"&G37&""&H37&"-"&I37&"W",""),IFERROR(C37&"-"&F37&"-"&G37&""&H37&"-"&I37&"W",""))) -> Conv-CFL-E27-1X-13W | C37: CFL | D37: Conv | E37: Interior | F37: E27 | H37: 1X | I37: 13 | J37: =IFERROR(K37*I37*VLOOKUP(C37,Mnu!$E$20:$F$37,2,FALSE)," ") -> 650 | K37: 1
A38: 37 | B38: =IF(C38="","",IF(D38="Conv",IFERROR(D38&"-"&C38&"-"&F38&"-"&G38&""&H38&"-"&I38&"W",""),IFERROR(C38&"-"&F38&"-"&G38&""&H38&"-"&I38&"W",""))) -> Conv-CFL-E27-1X-15W | C38: CFL | D38: Conv | E38: Interior | F38: E27 | H38: 1X | I38: 15 | J38: =IFERROR(K38*I38*VLOOKUP(C38,Mnu!$E$20:$F$37,2,FALSE)," ") -> 750 | K38: 1
A39: 38 | B39: =IF(C39="","",IF(D39="Conv",IFERROR(D39&"-"&C39&"-"&F39&"-"&G39&""&H39&"-"&I39&"W",""),IFERROR(C39&"-"&F39&"-"&G39&""&H39&"-"&I39&"W",""))) -> Conv-CFL-E27-1X-16W | C39: CFL | D39: Conv | E39: Interior | F39: E27 | H39: 1X | I39: 16 | J39: =IFERROR(K39*I39*VLOOKUP(C39,Mnu!$E$20:$F$37,2,FALSE)," ") -> 800 | K39: 1
A40: 39 | B40: =IF(C40="","",IF(D40="Conv",IFERROR(D40&"-"&C40&"-"&F40&"-"&G40&""&H40&"-"&I40&"W",""),IFERROR(C40&"-"&F40&"-"&G40&""&H40&"-"&I40&"W",""))) -> Conv-CFL-E27-1X-18W | C40: CFL | D40: Conv | E40: Interior | F40: E27 | H40: 1X | I40: 18 | J40: =IFERROR(K40*I40*VLOOKUP(C40,Mnu!$E$20:$F$37,2,FALSE)," ") -> 900 | K40: 1
A41: 40 | B41: =IF(C41="","",IF(D41="Conv",IFERROR(D41&"-"&C41&"-"&F41&"-"&G41&""&H41&"-"&I41&"W",""),IFERROR(C41&"-"&F41&"-"&G41&""&H41&"-"&I41&"W",""))) -> Conv-CFL-E27-1X-20W | C41: CFL | D41: Conv | E41: Interior | F41: E27 | H41: 1X | I41: 20 | J41: =IFERROR(K41*I41*VLOOKUP(C41,Mnu!$E$20:$F$37,2,FALSE)," ") -> 1000 | K41: 1
A42: 41 | B42: =IF(C42="","",IF(D42="Conv",IFERROR(D42&"-"&C42&"-"&F42&"-"&G42&""&H42&"-"&I42&"W",""),IFERROR(C42&"-"&F42&"-"&G42&""&H42&"-"&I42&"W",""))) -> Conv-CFL-E27-1X-23W | C42: CFL | D42: Conv | E42: Interior | F42: E27 | H42: 1X | I42: 23 | J42: =IFERROR(K42*I42*VLOOKUP(C42,Mnu!$E$20:$F$37,2,FALSE)," ") -> 1150 | K42: 1
A43: 42 | B43: =IF(C43="","",IF(D43="Conv",IFERROR(D43&"-"&C43&"-"&F43&"-"&G43&""&H43&"-"&I43&"W",""),IFERROR(C43&"-"&F43&"-"&G43&""&H43&"-"&I43&"W",""))) -> Conv-CFL-E27-1X-26W | C43: CFL | D43: Conv | E43: Interior | F43: E27 | H43: 1X | I43: 26 | J43: =IFERROR(K43*I43*VLOOKUP(C43,Mnu!$E$20:$F$37,2,FALSE)," ") -> 1300 | K43: 1
A44: 43 | B44: =IF(C44="","",IF(D44="Conv",IFERROR(D44&"-"&C44&"-"&F44&"-"&G44&""&H44&"-"&I44&"W",""),IFERROR(C44&"-"&F44&"-"&G44&""&H44&"-"&I44&"W",""))) -> Conv-CFL-E27-1X-30W | C44: CFL | D44: Conv | E44: Interior | F44: E27 | H44: 1X | I44: 30 | J44: =IFERROR(K44*I44*VLOOKUP(C44,Mnu!$E$20:$F$37,2,FALSE)," ") -> 1500 | K44: 1
A45: 44 | B45: =IF(C45="","",IF(D45="Conv",IFERROR(D45&"-"&C45&"-"&F45&"-"&G45&""&H45&"-"&I45&"W",""),IFERROR(C45&"-"&F45&"-"&G45&""&H45&"-"&I45&"W",""))) -> Conv-CFL-E27-1X-40W | C45: CFL | D45: Conv | E45: Interior | F45: E27 | H45: 1X | I45: 40 | J45: =IFERROR(K45*I45*VLOOKUP(C45,Mnu!$E$20:$F$37,2,FALSE)," ") -> 2000 | K45: 1
... A95: 94 | B95: =IF(C95="","",IF(D95="Conv",IFERROR(D95&"-"&C95&"-"&F95&"-"&G95&""&H95&"-"&I95&"W",""),IFERROR(C95&"-"&F95&"-"&G95&""&H95&"-"&I95&"W",""))) -> Conv-HPS-E40-1X-100W | C95: HPS | D95: Conv | E95: Interior | F95: E40 | H95: 1X | I95: 100 | J95: =IFERROR(K95*I95*VLOOKUP(C95,Mnu!$E$20:$F$37,2,FALSE)," ") -> 5000 | K95: 1
A96: 95 | B96: =IF(C96="","",IF(D96="Conv",IFERROR(D96&"-"&C96&"-"&F96&"-"&G96&""&H96&"-"&I96&"W",""),IFERROR(C96&"-"&F96&"-"&G96&""&H96&"-"&I96&"W",""))) -> LED_Tube-T8-1.5M-1X-30W | C96: LED_Tube | D96: LED | E96: Interior | F96: T8 | G96: 1.5M- | H96: 1X | I96: 30 | J96: =IFERROR(K96*I96*VLOOKUP(C96,Mnu!$E$20:$F$37,2,FALSE)," ") -> 2250 | K96: 1
A97: 96 | B97: =IF(C97="","",IF(D97="Conv",IFERROR(D97&"-"&C97&"-"&F97&"-"&G97&""&H97&"-"&I97&"W",""),IFERROR(C97&"-"&F97&"-"&G97&""&H97&"-"&I97&"W",""))) -> LED_Tube-T8-1.5M-2X-30W | C97: LED_Tube | D97: LED | E97: Interior | F97: T8 | G97: 1.5M- | H97: 2X | I97: 30 | J97: =IFERROR(K97*I97*VLOOKUP(C97,Mnu!$E$20:$F$37,2,FALSE)," ") -> 4500 | K97: 2
A98: 97 | B98: =IF(C98="","",IF(D98="Conv",IFERROR(D98&"-"&C98&"-"&F98&"-"&G98&""&H98&"-"&I98&"W",""),IFERROR(C98&"-"&F98&"-"&G98&""&H98&"-"&I98&"W",""))) -> LED_Tube-T8-1.5M-3X-30W | C98: LED_Tube | D98: LED | E98: Interior | F98: T8 | G98: 1.5M- | H98: 3X | I98: 30 | J98: =IFERROR(K98*I98*VLOOKUP(C98,Mnu!$E$20:$F$37,2,FALSE)," ") -> 6750 | K98: 3
A99: 98 | B99: =IF(C99="","",IF(D99="Conv",IFERROR(D99&"-"&C99&"-"&F99&"-"&G99&""&H99&"-"&I99&"W",""),IFERROR(C99&"-"&F99&"-"&G99&""&H99&"-"&I99&"W",""))) -> LED_Tube-T8-1.5M-4X-30W | C99: LED_Tube | D99: LED | E99: Interior | F99: T8 | G99: 1.5M- | H99: 4X | I99: 30 | J99: =IFERROR(K99*I99*VLOOKUP(C99,Mnu!$E$20:$F$37,2,FALSE)," ") -> 9000 | K99: 4
A100: 99 | B100: =IF(C100="","",IF(D100="Conv",IFERROR(D100&"-"&C100&"-"&F100&"-"&G100&""&H100&"-"&I100&"W",""),IFERROR(C100&"-"&F100&"-"&G100&""&H100&"-"&I100&"W",""))) -> LED_Tube-T8-1.2M-1X-20W | C100: LED_Tube | D100: LED | E100: Interior | F100: T8 | G100: 1.2M- | H100: 1X | I100: 20 | J100: =IFERROR(K100*I100*VLOOKUP(C100,Mnu!$E$20:$F$37,2,FALSE)," ") -> 1500 | K100: 1
A101: 100 | B101: =IF(C101="","",IF(D101="Conv",IFERROR(D101&"-"&C101&"-"&F101&"-"&G101&""&H101&"-"&I101&"W",""),IFERROR(C101&"-"&F101&"-"&G101&""&H101&"-"&I101&"W",""))) -> LED_Tube-T8-1.2M-2X-20W | C101: LED_Tube | D101: LED | E101: Interior | F101: T8 | G101: 1.2M- | H101: 2X | I101: 20 | J101: =IFERROR(K101*I101*VLOOKUP(C101,Mnu!$E$20:$F$37,2,FALSE)," ") -> 3000 | K101: 2
A102: 101 | B102: =IF(C102="","",IF(D102="Conv",IFERROR(D102&"-"&C102&"-"&F102&"-"&G102&""&H102&"-"&I102&"W",""),IFERROR(C102&"-"&F102&"-"&G102&""&H102&"-"&I102&"W",""))) -> LED_Tube-T8-1.2M-3X-20W | C102: LED_Tube | D102: LED | E102: Interior | F102: T8 | G102: 1.2M- | H102: 3X | I102: 20 | J102: =IFERROR(K102*I102*VLOOKUP(C102,Mnu!$E$20:$F$37,2,FALSE)," ") -> 4500 | K102: 3
A103: 102 | B103: =IF(C103="","",IF(D103="Conv",IFERROR(D103&"-"&C103&"-"&F103&"-"&G103&""&H103&"-"&I103&"W",""),IFERROR(C103&"-"&F103&"-"&G103&""&H103&"-"&I103&"W",""))) -> LED_Tube-T8-1.2M-4X-20W | C103: LED_Tube | D103: LED | E103: Interior | F103: T8 | G103: 1.2M- | H103: 4X | I103: 20 | J103: =IFERROR(K103*I103*VLOOKUP(C103,Mnu!$E$20:$F$37,2,FALSE)," ") -> 6000 | K103: 4
A104: 103 | B104: =IF(C104="","",IF(D104="Conv",IFERROR(D104&"-"&C104&"-"&F104&"-"&G104&""&H104&"-"&I104&"W",""),IFERROR(C104&"-"&F104&"-"&G104&""&H104&"-"&I104&"W",""))) -> LED_Tube-T8-1.2M-1X-18W | C104: LED_Tube | D104: LED | E104: Interior | F104: T8 | G104: 1.2M- | H104: 1X | I104: 18 | J104: =IFERROR(K104*I104*VLOOKUP(C104,Mnu!$E$20:$F$37,2,FALSE)," ") -> 1350 | K104: 1
...

Sheet Vstack
A1: Description | B1: Sr. No. | C1: Lamp Type | D1: Model | E1: Brand | F1: Shape/Size/Base | G1: Length/Width/Diameter | H1: Wattage (W) | I1: Lumens (lm) | J1: CCT (K) | K1: Life Hour Tested (Hrs.) | L1: Operating V/g (V)

Sheet Project_Light List
A1: Sr. No. | B1: Lamp Type | C1: Model | D1: Brand | E1: Shape/Size/Base | F1: Length/Width/Diameter | G1: Wattage (W) | H1: Lumens (lm) | I1: CCT (K) | J1: Life Hour Tested (Hrs.) | K1: Operating V/g (V) | M1: Sr. No. | N1: Lamp Type | O1: Model | P1: Brand | Q1: Shape/Size/Base | R1: Length/Width/Diameter | S1: Wattage (W) | T1: Lumens (lm) | U1: CCT (K) | V1: Life Hour Tested (Hrs.) | W1: Operating V/g (V) | Y1: Sr. No. | Z1: Lamp Type | AA1: Model | AB1: Brand | AC1: Shape/Size/Base | AD1: Length/Width/Diameter | AE1: Wattage (W) | AF1: Lumens (lm) | AG1: CCT (K) | AH1: Life Hour Tested (Hrs.) | AI1: Operating V/g (V) | AK1: Sr. No. | AL1: Lamp Type | AM1: Model | AN1: Brand | AO1: Shape/Size/Base | AP1: Length/Width/Diameter | AQ1: Wattage (W) | AR1: Lumens (lm) | AS1: CCT (K) | AT1: Life Hour Tested (Hrs.) | AU1: Operating V/g (V) | AW1: Sr. No. | AX1: Lamp Type | AY1: Model | AZ1: Brand | BA1: Shape/Size/Base | BB1: Length/Width/Diameter | BC1: Wattage (W) | BD1: Lumens (lm) | BE1: CCT (K) | BF1: Life Hour Tested (Hrs.) | BG1: Operating V/g (V)
A2: 1 | B2: LED Tube | C2: Ult TLED T5 7W 4000K 600mm IP20 ND | D2: Honeywell | E2: T5 | F2: 600 mm | G2: 7 | H2: 1155 | I2: 4000 | J2: 50000 | K2: 100-240 | M2: 1 | N2: LED Stick | O2: Ess Stick 7W 3000K T36 100-240V E27 IP20 ND | P2: Honeywell | Q2: E27 | R2: - | S2: 7 | T2: 840 | U2: 3000 | V2: 15000 | W2: 100-240 | Y2: 1 | Z2: LED Panel | AA2: LDPFM PL0606B 22W 840 WV (P-PL0606B-22W840-WV-K) | AB2: LEDVANCE | AC2: Square | AD2: 600 X 600 mm | AE2: 22 | AF2: 3300 | AG2: 4000 | AH2: 50000 | AI2: 100-277 | AK2: 1 | AL2: LED Down Light | AM2: LDSUP DL 105 6W 930 WV (P-DL-R105-6W-WV-G3-930) | AN2: LEDVANCE | AO2: Round-4" | AP2: 4" | AQ2: 6 | AR2: 750 | AS2: 3000 | AT2: 50000 | AU2: 100-277 | AW2: 1 | AX2: LED Flood Light | AY2: BVP151LED120/CW 120-277V 100W SWB 6500K | AZ2: Philips | BA2: - | BB2: - | BC2: 100 | BD2: 12000 | BE2: 6500 | BF2: 50000 | BG2: 120-277
A3: 2 | B3: LED Tube | C3: Ult TLED T5 7W 6500K 600mmIP20 ND | D3: Honeywell | E3: T5 | F3: 600 mm | G3: 7 | H3: 1155 | I3: 6500 | J3: 50000 | K3: 100-240 | M3: 2 | N3: LED Stick | O3: Ess Stick 7W 4000K T36 100-240V E27 IP20 ND | P3: Honeywell | Q3: E27 | R3: - | S3: 7 | T3: 840 | U3: 4000 | V3: 15000 | W3: 100-240 | Y3: 2 | Z3: LED Panel | AA3: LDPFM PL0606B 22W 865 WV (P-PL0606B-22W865-WV-K) | AB3: LEDVANCE | AC3: Square | AD3: 600 X 600 mm | AE3: 22 | AF3: 3300 | AG3: 6500 | AH3: 50000 | AI3: 100-277 | AK3: 2 | AL3: LED Down Light | AM3: LDSUP DL 105 6W 940 WV (P-DL-R105-6W-WV-G3-940) | AN3: LEDVANCE | AO3: Round-4" | AP3: 4" | AQ3: 6 | AR3: 780 | AS3: 4000 | AT3: 50000 | AU3: 100-277 | AW3: 2 | AX3: LED Flood Light | AY3: BVP151LED180/NW 120-277V 150W SWB 4000K | AZ3: Philips | BA3: - | BB3: - | BC3: 150 | BD3: 18000 | BE3: 4000 | BF3: 50000 | BG3: 120-277
A4: 3 | B4: LED Tube | C4: Ult TLED T5 10.5W 4000K 900mm IP20 ND | D4: Honeywell | E4: T5 | F4: 900 mm | G4: 10.5 | H4: 1735 | I4: 4000 | J4: 50000 | K4: 100-240 | M4: 3 | N4: LED Stick | O4: Ess Stick 7W 6500K T36 100-240V E27 IP20 ND | P4: Honeywell | Q4: E27 | R4: - | S4: 7 | T4: 840 | U4: 6500 | V4: 15000 | W4: 100-240 | Y4: 3 | Z4: LED Panel | AA4: LDPFM PL0606B 24W 830 (P-PL0606B-24W830-WV) | AB4: LEDVANCE | AC4: Square | AD4: 600 X 600 mm | AE4: 24 | AF4: 3600 | AG4: 3000 | AH4: 50000 | AI4: 100-277 | AK4: 3 | AL4: LED Down Light | AM4: LDSUP DL 105 6W 965 WV (P-DL-R105-6W-WV-G3-965) | AN4: LEDVANCE | AO4: Round-4" | AP4: 4" | AQ4: 6 | AR4: 780 | AS4: 6500 | AT4: 50000 | AU4: 100-277 | AW4: 3 | AX4: LED Flood Light | AY4: BVP151LED60/NW 120-277V 50W SWB 4000K | AZ4: Philips | BA4: - | BB4: - | BC4: 50 | BD4: 6000 | BE4: 4000 | BF4: 50000 | BG4: 100-277
A5: 4 | B5: LED Tube | C5: Ult TLED T5 10.5W 6500K 900mm IP20 ND | D5: Honeywell | E5: T5 | F5: 900 mm | G5: 10.5 | H5: 1735 | I5: 6500 | J5: 50000 | K5: 100-240 | M5: 4 | N5: LED Stick | O5: Ess Stick 9W 3000K T36 100-240V E27 IP20 ND | P5: Honeywell | Q5: E27 | R5: - | S5: 9 | T5: 1080 | U5: 3000 | V5: 15000 | W5: 100-240 | Y5: 4 | Z5: LED Panel | AA5: LDPFM PL0606B 24W 840 (P-PL0606B-24W840-WV) | AB5: LEDVANCE | AC5: Square | AD5: 600 X 600 mm | AE5: 24 | AF5: 3840 | AG5: 4000 | AH5: 50000 | AI5: 100-277 | AK5: 4 | AL5: LED Down Light | AM5: LDSUP DL 150 9W 930 WV (P-DL-R150-9W-WV-G3-930) | AN5: LEDVANCE | AO5: Round-6" | AP5: 6" | AQ5: 9 | AR5: 1200 | AS5: 3000 | AT5: 50000 | AU5: 100-277 | AW5: 4 | AX5: LED Flood Light | AY5: BVP151LED60/NW 120-277V 70W SWB 4000K | AZ5: Philips | BA5: - | BB5: - | BC5: 70 | BD5: 8400 | BE5: 4000 | BF5: 50000 | BG5: 100-277
A6: 5 | B6: LED Tube | C6: Ult TLED T5 14.5W 4000K 1200mmIP20 ND | D6: Honeywell | E6: T5 | F6: 1200 mm | G6: 14.5 | H6: 2395 | I6: 4000 | J6: 50000 | K6: 100-240 | M6: 5 | N6: LED Stick | O6: Ess Stick 9W 4000K T36 100-240V E27 IP20 ND | P6: Honeywell | Q6: E27 | R6: - | S6: 9 | T6: 1080 | U6: 4000 | V6: 15000 | W6: 100-240 | Y6: 5 | Z6: LED Panel | AA6: LDPFM PL0606B 24W 865 (P-PL0606B-24W865-WV) | AB6: LEDVANCE | AC6: Square | AD6: 600 X 600 mm | AE6: 24 | AF6: 3840 | AG6: 6500 | AH6: 50000 | AI6: 100-277 | AK6: 5 | AL6: LED Down Light | AM6: LDSUP DL 150 9W 940 WV (P-DL-R150-9W-WV-G3-940) | AN6: LEDVANCE | AO6: Round-6" | AP6: 6" | AQ6: 9 | AR6: 1260 | AS6: 4000 | AT6: 50000 | AU6: 100-277 | AW6: 5 | AX6: LED Street Light | AY6: Xceed BRP381 45W 120-277V 3000K | AZ6: Philips | BA6: - | BB6: - | BC6: 45 | BD6: 7000 | BE6: 3000 | BF6: 100000 | BG6: 100-277
A7: 6 | B7: LED Tube | C7: Ult TLED T5 14.5W 6500K 1200mmIP20 ND | D7: Honeywell | E7: T5 | F7: 1200 mm | G7: 14.5 | H7: 2395 | I7: 6500 | J7: 50000 | K7: 100-240 | M7: 6 | N7: LED Stick | O7: Ess Stick 9W 6500K T36 100-240V E27 IP20 ND | P7: Honeywell | Q7: E27 | R7: - | S7: 9 | T7: 1080 | U7: 6500 | V7: 15000 | W7: 100-240 | Y7: 6 | Z7: LED Panel | AA7: LDPFM PL0606 20W HE1 840 WV 6X1 KSALEDV | AB7: LEDVANCE | AC7: Square | AD7: 600 X 600 mm | AE7: 20 | AF7: 3800 | AG7: 4000 | AH7: 50000 | AI7: 100-240 | AK7: 6 | AL7: LED Down Light | AM7: LDSUP DL 150 9W 965 WV (P-DL-R150-9W-WV-G3-965) | AN7: LEDVANCE | AO7: Round-6" | AP7: 6" | AQ7: 9 | AR7: 1260 | AS7: 6500 | AT7: 50000 | AU7: 100-277 | AW7: 6 | AX7: LED Street Light | AY7: Xceed BRP381 45W 120-277V 4000K | AZ7: Philips | BA7: - | BB7: - | BC7: 45 | BD7: 7000 | BE7: 4000 | BF7: 100000 | BG7: 100-277
A8: 7 | B8: LED Tube | C8: Ult TLED T5 17W 4000K 1500mmIP20 ND | D8: Honeywell | E8: T5 | F8: 1500 mm | G8: 17 | H8: 2805 | I8: 4000 | J8: 50000 | K8: 100-240 | M8: 7 | N8: LED Stick | O8: Ess Stick 10W 3000K T36 100-240V E27 IP20 ND | P8: Honeywell | Q8: E27 | R8: - | S8: 10 | T8: 1200 | U8: 3000 | V8: 15000 | W8: 100-240 | Y8: 7 | Z8: LED Panel | AA8: LDPFM PL0606 20W HE1 865 WV 6X1 KSALEDV | AB8: LEDVANCE | AC8: Square | AD8: 600 X 600 mm | AE8: 20 | AF8: 3800 | AG8: 6500 | AH8: 50000 | AI8: 100-240 | AK8: 7 | AL8: LED Down Light | AM8: LDSUP DL 150 12W 930 WV (P-DL-R150-12W-WV-G3-930) | AN8: LEDVANCE | AO8: Round-6" | AP8: 6" | AQ8: 12 | AR8: 1600 | AS8: 3000 | AT8: 50000 | AU8: 100-277 | AW8: 7 | AX8: LED Street Light | AY8: Xceed BRP381 45W 120-277V 6500K | AZ8: Philips | BA8: - | BB8: - | BC8: 45 | BD8: 7000 | BE8: 6500 | BF8: 100000 | BG8: 100-277
A9: 8 | B9: LED Tube | C9: Ult TLED T5 17W 6500K 1500mm IP20 ND | D9: Honeywell | E9: T5 | F9: 1500 mm | G9: 17 | H9: 2805 | I9: 6500 | J9: 50000 | K9: 100-240 | M9: 8 | N9: LED Stick | O9: Ess Stick 10W 4000K T36 100-240V E27 IP20 ND | P9: Honeywell | Q9: E27 | R9: - | S9: 10 | T9: 1200 | U9: 4000 | V9: 15000 | W9: 100-240 | Y9: 8 | Z9: LED Panel | AA9: LDPFM PL0606B 28W 830 WV (P-PL0606B-28W830-WV-H) | AB9: LEDVANCE | AC9: Square | AD9: 600 X 600 mm | AE9: 28 | AF9: 3680 | AG9: 3000 | AH9: 50000 | AI9: 100-277 | AK9: 8 | AL9: LED Down Light | AM9: LDSUP DL 150 12W 940 WV (P-DL-R150-12W-WV-G3-940) | AN9: LEDVANCE | AO9: Round-6" | AP9: 6" | AQ9: 12 | AR9: 1680 | AS9: 4000 | AT9: 50000 | AU9: 100-277 | AW9: 8 | AX9: LED Street Light | AY9: Xceed BRP384 302W 120-277 4000K | AZ9: Philips | BA9: - | BB9: - | BC9: 302 | BD9: 45000 | BE9: 4000 | BF9: 100000 | BG9: 120-277
A10: 9 | B10: LED Tube | C10: Ult TLED T5 24W 4000K 1500mm IP20 ND | D10: Honeywell | E10: T5 | F10: 1500 mm | G10: 24 | H10: 3960 | I10: 4000 | J10: 50000 | K10: 100-240 | M10: 9 | N10: LED Stick | O10: Ess Stick 10W 6500K T36 100-240V E27 IP20 ND | P10: Honeywell | Q10: E27 | R10: - | S10: 10 | T10: 1200 | U10: 6500 | V10: 15000 | W10: 100-240 | Y10: 9 | Z10: LED Panel | AA10: LDPFM PL0606B 28W 840 WV (P-PL0606B-28W840-WV-H) | AB10: LEDVANCE | AC10: Square | AD10: 600 X 600 mm | AE10: 28 | AF10: 4000 | AG10: 4000 | AH10: 50000 | AI10: 100-277 | AK10: 9 | AL10: LED Down Light | AM10: LDSUP DL 150 12W 965 WV (P-DL-R150-12W-WV-G3-965) | AN10: LEDVANCE | AO10: Round-6" | AP10: 6" | AQ10: 12 | AR10: 1680 | AS10: 6500 | AT10: 50000 | AU10: 100-277 | AW10: 9 | AX10: LED Street Light | AY10: Xceed BRP384 26W 120-277 4000K | AZ10: Philips | BA10: - | BB10: - | BC10: 26 | BD10: 3750 | BE10: 4000 | BF10: 100000 | BG10: 120-277
A11: 10 | B11: LED Tube | C11: Ult TLED T5 24W 6500K 1500mm IP20 ND | D11: Honeywell | E11: T5 | F11: 1500 mm | G11: 24 | H11: 3960 | I11: 6500 | J11: 50000 | K11: 100-240 | M11: 10 | N11: LED Stick | O11: Ess Stick 12W 3000K T44 100-240V E27 IP20 ND | P11: Honeywell | Q11: E27 | R11: - | S11: 12 | T11: 1440 | U11: 3000 | V11: 15000 | W11: 100-240 | Y11: 10 | Z11: LED Panel | AA11: LDPFM PL0606B 28W 865 WV (P-PL0606B-28W865-WV-H) | AB11: LEDVANCE | AC11: Square | AD11: 600 X 600 mm | AE11: 28 | AF11: 4000 | AG11: 6500 | AH11: 50000 | AI11: 100-277 | AK11: 10 | AL11: LED Down Light | AM11: LDSUP DL 190 15W 930 WV (P-DL-R190-15W-WV-G3-930) | AN11: LEDVANCE | AO11: Round-8" | AP11: 8" | AQ11: 15 | AR11: 2000 | AS11: 3000 | AT11: 50000 | AU11: 100-277 | AW11: 10 | AX11: LED Street Light | AY11: Xceed BRP384 264W 120‐277V 6500K | AZ11: Philips | BA11: - | BB11: - | BC11: 264 | BD11: 40000 | BE11: 6500 | BF11: 100000 | BG11: 100-277
A12: 11 | B12: LED Tube | C12: Ult TLED T8 5.5W 3000K 60cm G13 IP20 ND | D12: Honeywell | E12: T8 | F12: 600 mm | G12: 5.5 | H12: 900 | I12: 3000 | J12: 50000 | K12: 100-240 | M12: 11 | N12: LED Stick | O12: Ess Stick 12W 4000K T44 100-240V E27 IP20 ND | P12: Honeywell | Q12: E27 | R12: - | S12: 12 | T12: 1440 | U12: 4000 | V12: 15000 | W12: 100-240 | Y12: 11 | Z12: LED Panel | AA12: LDVAL PANEL 0312 36W 840 | AB12: Ledvance | AC12: Rectangular | AD12: 300 X 1200 mm | AE12: 36 | AF12: 4000 | AG12: 4000 | AH12: 50000 | AI12: 220-240 | AK12: 11 | AL12: LED Down Light | AM12: LDSUP DL 190 15W 940 WV (P-DL-R190-15W-WV-G3-940) | AN12: LEDVANCE | AO12: Round-8" | AP12: 8" | AQ12: 15 | AR12: 2100 | AS12: 4000 | AT12: 50000 | AU12: 100-277 | AW12: 11 | AX12: LED Street Light | AY12: Xceed BRP381 3000K 102W 120-277V | AZ12: Philips | BA12: - | BB12: - | BC12: 102 | BD12: 15000 | BE12: 3000 | BF12: 100000 | BG12: 100-277
A13: 12 | B13: LED Tube | C13: Ult TLED T8 5.5W 4000K 60cm G13 IP20 ND | D13: Honeywell | E13: T8 | F13: 600 mm | G13: 5.5 | H13: 1000 | I13: 4000 | J13: 50000 | K13: 100-240 | M13: 12 | N13: LED Stick | O13: Ess Stick 12W 6500K T44 100-240V E27 IP20 ND | P13: Honeywell | Q13: E27 | R13: - | S13: 12 | T13: 1440 | U13: 6500 | V13: 15000 | W13: 100-240 | Y13: 12 | Z13: LED Panel | AA13: LDVAL PANEL 0312 36W 865 | AB13: Ledvance | AC13: Rectangular | AD13: 300 X 1200 mm | AE13: 36 | AF13: 4000 | AG13: 6500 | AH13: 50000 | AI13: 220-240 | AK13: 12 | AL13: LED Down Light | AM13: LDSUP DL 190 15W 965 WV (P-DL-R190-15W-WV-G3-965) | AN13: LEDVANCE | AO13: Round-8" | AP13: 8" | AQ13: 15 | AR13: 2100 | AS13: 6500 | AT13: 50000 | AU13: 100-277 | AW13: 12 | AX13: LED Street Light | AY13: Xceed BRP381 4000K 102W 120-277V | AZ13: Philips | BA13: - | BB13: - | BC13: 102 | BD13: 15000 | BE13: 4000 | BF13: 100000 | BG13: 100-277
... A26: 25 | B26: LED Tube | C26: Adv TLED T8 20W 4000K 150cm G13 IP20 ND | D26: Honeywell | E26: T8 | F26: 1500 mm | G26: 20 | H26: 3200 | I26: 4000 | J26: 50000 | K26: 100-240 | M26: 25 | N26: LED Bulb | O26: Ess Bulb 9W 4000K A60 220-240V E27 IP20 ND | P26: Honeywell | Q26: E27 | R26: - | S26: 9 | T26: 900 | U26: 4000 | V26: 15000 | W26: 220-240 | Y26: 25 | Z26: LED Panel | AA26: Ult BL 25W 4000K 100-277V 30X120 IP20/54 ND UGR<19 | AB26: Honeywell | AC26: Rectangular | AD26: 300 X 1200 mm | AE26: 25 | AF26: 4000 | AG26: 4000 | AH26: 50000 | AI26: 100-240 | AK26: 25 | AL26: LED Down Light | AM26: LDVAL SLIMDL RD 150 15W830 | AN26: Osram | AO26: Round-6" | AP26: 6" | AQ26: 15 | AR26: 1080 | AS26: 3000 | AT26: 30000 | AU26: 220-240 | AW26: 25 | AX26: LED Flood Light | AY26: LDPFM FL HP400W 865 | AZ26: Ledvance | BA26: - | BB26: 30D,55D,40X85D | BC26: 400 | BD26: 40000 | BE26: 6500 | BF26: 50000 | BG26: 100-240
A27: 26 | B27: LED Tube | C27: Adv TLED T8 20W 6500K 150cm G13 IP20 ND | D27: Honeywell | E27: T8 | F27: 1500 mm | G27: 20 | H27: 3200 | I27: 6500 | J27: 50000 | K27: 100-240 | M27: 26 | N27: LED Bulb | O27: Ess Bulb 9W 6500K A60 220-240V E27 IP20 ND | P27: Honeywell | Q27: E27 | R27: - | S27: 9 | T27: 900 | U27: 6500 | V27: 15000 | W27: 220-240 | Y27: 26 | Z27: LED Panel | AA27: Ult BL 25W 6500K 100-277V 30X120 IP20/54 ND UGR<19 | AB27: Honeywell | AC27: Rectangular | AD27: 300 X 1200 mm | AE27: 25 | AF27: 4000 | AG27: 6500 | AH27: 50000 | AI27: 100-240 | AK27: 26 | AL27: LED Down Light | AM27: LDVAL SLIMDL RD 150 15W840 | AN27: Osram | AO27: Round-6" | AP27: 6" | AQ27: 15 | AR27: 1200 | AS27: 4000 | AT27: 30000 | AU27: 220-240 | AW27: 26 | AX27: LED Flood Light | AY27: LDPFM FL HP 600W 865 | AZ27: Ledvance | BB27: 30D,55D,40X85D | BC27: 600 | BD27: 60000 | BE27: 6500 | BF27: 50000 | BG27: 100-240
A28: 27 | B28: LED Batten Light | C28: Adv WP 16W 4000K IP65 ND | D28: Honeywell | E28: Rectangle line | F28: 600 mm | G28: 16 | H28: 2560 | I28: 4000 | J28: 50000 | K28: 100-240 | M28: 27 | N28: LED Bulb | O28: Ess Bulb 12W 3000K A60 220-240V E27 IP20 ND | P28: Honeywell | Q28: E27 | R28: - | S28: 12 | T28: 1200 | U28: 3000 | V28: 15000 | W28: 220-240 | Y28: 27 | Z28: LED Panel | AA28: Ult BL 38W 4000K 100-277V 60X120 IP20/54 ND UGR<19 | AB28: Honeywell | AC28: Rectangular | AD28: 600 X 1200 mm | AE28: 38 | AF28: 6080 | AG28: 4000 | AH28: 50000 | AI28: 100-240 | AK28: 27 | AL28: LED Down Light | AM28: LDVAL SLIMDL RD 150 15W865 | AN28: Osram | AO28: Round-6" | AP28: 6" | AQ28: 15 | AR28: 1200 | AS28: 6500 | AT28: 30000 | AU28: 220-240 | AW28: 27 | AX28: LED Flood Light | AY28: LDPFM FL HP 600W 840 | AZ28: Ledvance | BA28: - | BB28: 30D,55D,40X85D | BC28: 600 | BD28: 60000 | BE28: 4000 | BF28: 50000 | BG28: 100-240
A29: 28 | B29: LED Batten Light | C29: Adv WP 16W 6500K IP65 ND | D29: Honeywell | E29: Rectangle line | F29: 600 mm | G29: 16 | H29: 2560 | I29: 6500 | J29: 50000 | K29: 100-240 | M29: 28 | N29: LED Bulb | O29: Ess Bulb 12W 4000K A60 220-240V E27 IP20 ND | P29: Honeywell | Q29: E27 | R29: - | S29: 12 | T29: 1200 | U29: 4000 | V29: 15000 | W29: 220-240 | Y29: 28 | Z29: LED Panel | AA29: Ult BL 38W 6500K 100-277V 60X120 IP20/54 ND UGR<19 | AB29: Honeywell | AC29: Rectangular | AD29: 600 X 1200 mm | AE29: 38 | AF29: 6080 | AG29: 6500 | AH29: 50000 | AI29: 100-240 | AK29: 28 | AL29: LED Down Light | AM29: LDVAL SLIMDL RD 205 18W830 | AN29: Osram | AO29: Round-8" | AP29: 8" | AQ29: 18 | AR29: 1600 | AS29: 3000 | AT29: 30000 | AU29: 220-240 | AW29: 28 | AX29: LED Flood Light | AY29: LDPFM FL 10W 830 (P-FL-10W-WV-G4-830) | AZ29: LEDVANCE | BA29: Square | BB29: 131x92x36mm | BC29: 10 | BD29: 1450 | BE29: 3000 | BF29: 100000 | BG29: 100-277
A30: 29 | B30: LED Batten Light | C30: Adv WP 30W 4000K IP65 ND | D30: Honeywell | E30: Rectangle line | F30: 1200 mm | G30: 30 | H30: 4800 | I30: 4000 | J30: 50000 | K30: 100-240 | M30: 29 | N30: LED Bulb | O30: Ess Bulb 12W 6500K A60 220-240V E27 IP20 ND | P30: Honeywell | Q30: E27 | R30: - | S30: 12 | T30: 1200 | U30: 6500 | V30: 15000 | W30: 220-240 | Y30: 29 | Z30: LED Surface Light | AA30: Ess Surface R SMD DL 18W 3000K 220-240V IP20 ND | AB30: Honeywell | AC30: Round | AD30: 223 mm | AE30: 18 | AF30: 1325 | AG30: 3000 | AH30: 25000 | AI30: 220-240 | AK30: 29 | AL30: LED Down Light | AM30: LDVAL SLIMDL RD 205 18W840 | AN30: Osram | AO30: Round-8" | AP30: 8" | AQ30: 18 | AR30: 1750 | AS30: 4000 | AT30: 30000 | AU30: 220-240 | AW30: 29 | AX30: LED Flood Light | AY30: LDPFM FL 10W 840 (P-FL-10W-WV-G4-840) | AZ30: LEDVANCE | BA30: Square | BB30: 131x92x36mm | BC30: 10 | BD30: 1550 | BE30: 4000 | BF30: 100000 | BG30: 100-277
A31: 30 | B31: LED Batten Light | C31: Adv WP 30W 6500K IP65 ND | D31: Honeywell | E31: Rectangle line | F31: 1200 mm | G31: 30 | H31: 4800 | I31: 6500 | J31: 50000 | K31: 100-240 | M31: 30 | N31: LED Bulb | O31: Ess Bulb 17.7W 3000K A65 220-240V E27 IP20 ND | P31: Honeywell | Q31: E27 | R31: - | S31: 17.7 | T31: 1770 | U31: 3000 | V31: 15000 | W31: 220-240 | Y31: 30 | Z31: LED Surface Light | AA31: Ess Surface R SMD DL 18W 4000K 220-240V IP20 ND | AB31: Honeywell | AC31: Round | AD31: 223 mm | AE31: 18 | AF31: 1440 | AG31: 4000 | AH31: 25000 | AI31: 220-240 | AK31: 30 | AL31: LED Down Light | AM31: LDVAL SLIMDL RD 205 18W865 | AN31: Osram | AO31: Round-8" | AP31: 8" | AQ31: 18 | AR31: 1750 | AS31: 6500 | AT31: 30000 | AU31: 220-240 | AW31: 30 | AX31: LED Flood Light | AY31: LDPFM FL 10W 865 (P-FL-10W-WV-G4-865) | AZ31: LEDVANCE | BA31: Square | BB31: 131x92x36mm | BC31: 10 | BD31: 1550 | BE31: 6500 | BF31: 100000 | BG31: 100-277
A32: 31 | B32: LED Batten Light | C32: Adv WP 45W 4000K IP65 ND | D32: Honeywell | E32: Rectangle line | F32: 1500 mm | G32: 45 | H32: 7200 | I32: 4000 | J32: 50000 | K32: 100-240 | M32: 31 | N32: LED Bulb | O32: Ess Bulb 17.7W 4000K A65 220-240V E27 IP20 ND | P32: Honeywell | Q32: E27 | R32: - | S32: 17.7 | T32: 1770 | U32: 4000 | V32: 15000 | W32: 220-240 | Y32: 31 | Z32: LED Panel | AA32: RC199VLED40/830 PSU W60L60 UE KSA | AB32: Philips | AC32: Square | AD32: 600 X 600 mm | AE32: 21 | AF32: 4000 | AG32: 3000 | AH32: 50000 | AI32: 220-240 | AK32: 31 | AL32: LED Down Light | AM32: Ultimate Downlight UE UGR 5.5W 3000K 100-240V ND | AN32: Honeywell | AO32: Round-4" | AP32: 4 | AQ32: 5.5 | AR32: 693 | AS32: 3000 | AT32: 50000 | AU32: 100-240 | AW32: 31 | AX32: LED Flood Light | AY32: LDPFM FL 15W 830 (P-FL-15W-WV-G4-830) | AZ32: LEDVANCE | BA32: Square | BB32: 156x109x42mm | BC32: 15 | BD32: 2150 | BE32: 3000 | BF32: 100000 | BG32: 100-277
A33: 32 | B33: LED Batten Light | C33: Adv WP 45W 6500K IP65 ND | D33: Honeywell | E33: Rectangle line | F33: 1500 mm | G33: 45 | H33: 7200 | I33: 6500 | J33: 50000 | K33: 100-240 | M33: 32 | N33: LED Bulb | O33: Ess Bulb 17.7W 6500K A65 220-240V E27 IP20 ND | P33: Honeywell | Q33: E27 | R33: - | S33: 17.7 | T33: 1770 | U33: 6500 | V33: 15000 | W33: 220-240 | Y33: 32 | Z33: LED Panel | AA33: RC199VLED57/830 PSU W60L120 UE KSA | AB33: Philips | AC33: Rectangular | AD33: 600 X 1200 mm | AE33: 33 | AF33: 5700 | AG33: 3000 | AH33: 50000 | AI33: 220-240 | AK33: 32 | AL33: LED Down Light | AM33: Ultimate Downlight UE UGR 5.5W 4000K 100-240V ND | AN33: Honeywell | AO33: Round-4" | AP33: 4 | AQ33: 5.5 | AR33: 721 | AS33: 4000 | AT33: 50000 | AU33: 100-240 | AW33: 32 | AX33: LED Flood Light | AY33: LDPFM FL 15W 840 (P-FL-15W-WV-G4-840) | AZ33: LEDVANCE | BA33: Square | BB33: 156x109x42mm | BC33: 15 | BD33: 2350 | BE33: 4000 | BF33: 100000 | BG33: 100-277
A34: 33 | B34: LED Tube | C34: ST8A-0.6M 5,3W/830100-240VEM25X1KSAOSRAM | D34: Osram | E34: T8 | F34: 600 mm | G34: 5.3 | H34: 900 | I34: 3000 | J34: 50000 | K34: 100-240 | M34: 33 | N34: LED Candle Light | O34: Ess Candle 5W 3000K B35 220-240V E14 IP20 ND | P34: Honeywell | Q34: E14 | R34: - | S34: 5 | T34: 500 | U34: 3000 | V34: 15000 | W34: 220-240 | Y34: 33 | Z34: LED Panel | AA34: RC099V G3LED38/830 PSU W60L60 HE | AB34: Philips | AC34: Square | AD34: 600 X 600 mm | AE34: 27 | AF34: 3800 | AG34: 3000 | AH34: 50000 | AI34: 220-240 | AK34: 33 | AL34: LED Down Light | AM34: Ultimate Downlight UE UGR 5.5W 6500K 100-240V ND | AN34: Honeywell | AO34: Round-4" | AP34: 4 | AQ34: 5.5 | AR34: 721 | AS34: 6500 | AT34: 50000 | AU34: 100-240 | AW34: 33 | AX34: LED Flood Light | AY34: LDPFM FL 15W 865 (P-FL-15W-WV-G4-865) | AZ34: LEDVANCE | BA34: Square | BB34: 156x109x42mm | BC34: 15 | BD34: 2350 | BE34: 6500 | BF34: 100000 | BG34: 100-277
A35: 34 | B35: LED Tube | C35: ST8A-0.6M 5,3W/840100-240VEM25X1KSAOSRAM | D35: Osram | E35: T8 | F35: 600 mm | G35: 5.3 | H35: 1000 | I35: 4000 | J35: 50000 | K35: 100-240 | M35: 34 | N35: LED Candle Light | O35: Ess Candle 5W 4000K B35 220-240V E14 IP20 ND | P35: Honeywell | Q35: E14 | R35: - | S35: 5 | T35: 500 | U35: 4000 | V35: 15000 | W35: 220-240 | Y35: 34 | Z35: LED Panel | AA35: RC199VLED40/840 PSU W60L60 UE KSA | AB35: Philips | AC35: Square | AD35: 600 X 600 mm | AE35: 21 | AF35: 4000 | AG35: 4000 | AH35: 50000 | AI35: 220-240 | AK35: 34 | AL35: LED Down Light | AM35: Ultimate Downlight UE UGR 8.5W 3000K 100-240V ND | AN35: Honeywell | AO35: Round-6" | AP35: 6 | AQ35: 8.5 | AR35: 1139 | AS35: 3000 | AT35: 50000 | AU35: 100-240 | AW35: 34 | AX35: LED Flood Light | AY35: LDPFM FL 25W 830 (P-FL-25W-WV-G4-830) | AZ35: LEDVANCE | BA35: Square | BB35: 186x134x42mm | BC35: 25 | BD35: 3750 | BE35: 3000 | BF35: 100000 | BG35: 100-277
A36: 35 | B36: LED Tube | C36: ST8A-0.6M 5,3W/865100-240VEM25X1KSAOSRAM | D36: Osram | E36: T8 | F36: 600 mm | G36: 5.3 | H36: 1000 | I36: 6500 | J36: 50000 | K36: 100-240 | M36: 35 | N36: LED Candle Light | O36: Ess Candle 5W 6500K B35 220-240V E14 IP20 ND | P36: Honeywell | Q36: E14 | R36: - | S36: 5 | T36: 500 | U36: 6500 | V36: 15000 | W36: 220-240 | Y36: 35 | Z36: LED Panel | AA36: RC199VLED57/840 PSU W60L120 UE KSA | AB36: Philips | AC36: Rectangular | AD36: 600 X 1200 mm | AE36: 33 | AF36: 5700 | AG36: 4000 | AH36: 50000 | AI36: 220-240 | AK36: 35 | AL36: LED Down Light | AM36: Ultimate Downlight UE UGR 8.5W 4000K 100-240V ND | AN36: Honeywell | AO36: Round-6" | AP36: 6 | AQ36: 8.5 | AR36: 1207 | AS36: 4000 | AT36: 50000 | AU36: 100-240 | AW36: 35 | AX36: LED Flood Light | AY36: LDPFM FL 25W 840 (P-FL-25W-WV-G4-840) | AZ36: LEDVANCE | BA36: Square | BB36: 186x134x42mm | BC36: 25 | BD36: 4000 | BE36: 4000 | BF36: 100000 | BG36: 100-277
A37: 36 | B37: LED Tube | C37: ST8A-0.9M 9W/830 100-240V EM25X1KSAOSRAM | D37: Osram | E37: T8 | F37: 900 mm | G37: 9 | H37: 1458 | I37: 3000 | J37: 50000 | K37: 100-240 | M37: 36 | N37: LED Spot Light | O37: Ult Spot GU10 2.85W 2700K 38D 220-240V GU10 IP20 | P37: Honeywell | Q37: GU10 | R37: - | S37: 2.85 | T37: 450 | U37: 2700 | V37: 25000 | W37: 220-240 | Y37: 36 | Z37: LED Panel | AA37: RC099V G3LED38/840 PSU W60L60 HE | AB37: Philips | AC37: Square | AD37: 600 X 600 mm | AE37: 27 | AF37: 3800 | AG37: 4000 | AH37: 50000 | AI37: 220-240 | AK37: 36 | AL37: LED Down Light | AM37: Ultimate Downlight UE UGR 8.5W 6500K 100-240V ND | AN37: Honeywell | AO37: Round-6" | AP37: 6 | AQ37: 8.5 | AR37: 1207 | AS37: 6500 | AT37: 50000 | AU37: 100-240 | AW37: 36 | AX37: LED Flood Light | AY37: LDPFM FL 25W 865 (P-FL-25W-WV-G4-865) | AZ37: LEDVANCE | BA37: Square | BB37: 186x134x42mm | BC37: 25 | BD37: 4000 | BE37: 6500 | BF37: 100000 | BG37: 100-277
A38: 37 | B38: LED Tube | C38: ST8A-0.9M 9W/840 100-240V EM25X1KSAOSRAM | D38: Osram | E38: T8 | F38: 900 mm | G38: 9 | H38: 1620 | I38: 4000 | J38: 50000 | K38: 100-240 | M38: 37 | N38: LED Spot Light | O38: Ult Spot GU10 2.85W 4000K 38D 220-240V GU10 IP20 | P38: Honeywell | Q38: GU10 | R38: - | S38: 2.85 | T38: 500 | U38: 4000 | V38: 25000 | W38: 220-240 | Y38: 37 | Z38: LED Panel | AA38: RC199VLED40/865 PSU W60L60 UE KSA | AB38: Philips | AC38: Square | AD38: 600 X 600 mm | AE38: 21 | AF38: 4000 | AG38: 6500 | AH38: 50000 | AI38: 220-240 | AK38: 37 | AL38: LED Down Light | AM38: Ultimate Downlight UE UGR 11W 3000K 100-240V ND | AN38: Honeywell | AO38: Round-6" | AP38: 6 | AQ38: 11 | AR38: 1474 | AS38: 3000 | AT38: 50000 | AU38: 100-240 | AW38: 37 | AX38: LED Flood Light | AY38: LDPFM FL 43W 830 (P-FL-43W-WV-G4-830) | AZ38: LEDVANCE | BA38: Square | BB38: 218x155x46mm | BC38: 43 | BD38: 6500 | BE38: 3000 | BF38: 100000 | BG38: 100-277
A39: 38 | B39: LED Tube | C39: ST8A-0.9M 9W/865 100-240V EM25X1KSAOSRAM | D39: Osram | E39: T8 | F39: 900 mm | G39: 9 | H39: 1620 | I39: 6500 | J39: 50000 | K39: 100-240 | M39: 38 | N39: LED Spot Light | O39: Ult Spot GU10 2.85W 6500K 38D 220-240V GU10 IP20 | P39: Honeywell | Q39: GU10 | R39: - | S39: 2.85 | T39: 500 | U39: 6500 | V39: 25000 | W39: 220-240 | Y39: 38 | Z39: LED Panel | AA39: RC199VLED57/865 PSU W60L120 UE KSA | AB39: Philips | AC39: Rectangular | AD39: 600 X 1200 mm | AE39: 33 | AF39: 5700 | AG39: 6500 | AH39: 50000 | AI39: 220-240 | AK39: 38 | AL39: LED Down Light | AM39: Ultimate Downlight UE UGR 11W 4000K 100-240V ND | AN39: Honeywell | AO39: Round-6" | AP39: 6 | AQ39: 11 | AR39: 1562 | AS39: 4000 | AT39: 50000 | AU39: 100-240 | AW39: 38 | AX39: LED Flood Light | AY39: LDPFM FL 43W 840 (P-FL-43W-WV-G4-840) | AZ39: LEDVANCE | BA39: Square | BB39: 218x155x46mm | BC39: 43 | BD39: 7000 | BE39: 4000 | BF39: 100000 | BG39: 100-277
